Workbook

Sheet 00_评审看板
A1: PRD 需求自查清单 V3.3｜质量门禁看板
A2: 根标准：读的人不需要再回来找 PM 确认。看板根据 01_需求自查清单 的适用性、填写情况、门禁状态自动汇总。
A4: 指标 | B4: 公式/结果 | C4: 说明 | D4: 门禁状态 | E4: 数量 | G4: 优先级 | H4: 适用项 | I4: 未通过/未处理
A5: 检查项总数 | B5: =COUNTA('01_需求自查清单'!$A$2:$A$200) -> 66 | C5: 清单内全部检查项数量 | D5: 通过 | E5: =COUNTIF('01_需求自查清单'!$R$2:$R$200,D5) -> 0 | G5: P0 | H5: =COUNTIFS('01_需求自查清单'!$L$2:$L$200,G5,'01_需求自查清单'!$N$2:$N$200,"是") -> 22 | I5: =COUNTIFS('01_需求自查清单'!$L$2:$L$200,G5,'01_需求自查清单'!$N$2:$N$200,"是",'01_需求自查清单'!$R$2:$R$200,"<>通过") -> 22
A6: 适用项数量 | B6: =COUNTIF('01_需求自查清单'!$N$2:$N$200,"是") -> 66 | C6: 当前需求需要检查的项目数 | D6: 待补充 | E6: =COUNTIF('01_需求自查清单'!$R$2:$R$200,D6) -> 0 | G6: P1 | H6: =COUNTIFS('01_需求自查清单'!$L$2:$L$200,G6,'01_需求自查清单'!$N$2:$N$200,"是") -> 31 | I6: =COUNTIFS('01_需求自查清单'!$L$2:$L$200,G6,'01_需求自查清单'!$N$2:$N$200,"是",'01_需求自查清单'!$R$2:$R$200,"<>通过") -> 31
A7: 通过项数量 | B7: =COUNTIF('01_需求自查清单'!$R$2:$R$200,"通过") -> 0 | C7: 已写且已检查的通过项 | D7: P0阻塞 | E7: =COUNTIF('01_需求自查清单'!$R$2:$R$200,D7) -> 0 | G7: P2 | H7: =COUNTIFS('01_需求自查清单'!$L$2:$L$200,G7,'01_需求自查清单'!$N$2:$N$200,"是") -> 10 | I7: =COUNTIFS('01_需求自查清单'!$L$2:$L$200,G7,'01_需求自查清单'!$N$2:$N$200,"是",'01_需求自查清单'!$R$2:$R$200,"<>通过") -> 10
A8: P0 阻塞项 | B8: =COUNTIF('01_需求自查清单'!$R$2:$R$200,"P0阻塞")+COUNTIF('01_需求自查清单'!$Q$2:$Q$200,"P0") -> 0 | C8: 存在任何 P0 均不可进入评审 | D8: P1风险 | E8: =COUNTIF('01_需求自查清单'!$R$2:$R$200,D8) -> 0 | G8: P3 | H8: =COUNTIFS('01_需求自查清单'!$L$2:$L$200,G8,'01_需求自查清单'!$N$2:$N$200,"是") -> 3 | I8: =COUNTIFS('01_需求自查清单'!$L$2:$L$200,G8,'01_需求自查清单'!$N$2:$N$200,"是",'01_需求自查清单'!$R$2:$R$200,"<>通过") -> 3
A9: P1 风险项 | B9: =COUNTIF('01_需求自查清单'!$R$2:$R$200,"P1风险")+COUNTIF('01_需求自查清单'!$Q$2:$Q$200,"P1") -> 0 | C9: P1 默认阻塞，除非记录风险接受 | D9: 建议优化 | E9: =COUNTIF('01_需求自查清单'!$R$2:$R$200,D9) -> 0
A10: 待检查项 | B10: =COUNTIF('01_需求自查清单'!$R$2:$R$200,"待检查") -> 66 | C10: 适用但尚未填写检查结果 | D10: 待检查 | E10: =COUNTIF('01_需求自查清单'!$R$2:$R$200,D10) -> 66
A11: 待补充项 | B11: =COUNTIF('01_需求自查清单'!$R$2:$R$200,"待补充") -> 0 | C11: PRD 已部分覆盖但仍需补充 | D11: 不适用 | E11: =COUNTIF('01_需求自查清单'!$R$2:$R$200,D11) -> 0
A12: 适用项通过率 | B12: =IF(B6=0,0,B7/B6) -> 0 | C12: 通过项 / 适用项
A13: 必查门禁通过率 | B13: =IF(COUNTIFS('01_需求自查清单'!$B$2:$B$200,"必查门禁",'01_需求自查清单'!$N$2:$N$200,"是")=0,0,COUNTIFS('01_需求自查清单'!$B$2:$B$200,"必查门禁",'01_需求自查清单'!$N$2:$N$200,"是",'01_需求自查清单'!$R$2:$R$200,"通过")/COUNTIFS('01_需求自查清单'!$B$2:$B$200,"必查门禁",'01_需求自查清单'!$N$2:$N$200,"是")) -> 0 | C13: 必查门禁内通过比例 | F13: 四大质量指标 | G13: 核心自查问题 | H13: 优先关注
A14: 评审结论 | B14: =IF(B8>0,"不可进入评审：存在 P0 阻塞",IF(B9>0,"默认不建议进入评审：存在 P1 风险，需修正或记录风险接受",IF(B10>0,"待检查：尚有 "&B10&" 项未完成检查",IF(B11>0,"待补充：尚有 "&B11&" 项需要补充","可进入评审")))) -> 待检查：尚有 66 项未完成检查 | C14: 自动结论 | F14: 边界清晰 | G14: 本期做什么、不做什么、适用于谁、不适用于谁是否明确？ | H14: 范围、非目标、角色、权限、数据边界
F15: 判断显性 | G15: 规则、默认值、异常、依赖、责任方是否写出结论？ | H15: 核心规则、默认规则、操作控制、异常兜底
F16: 不留猜疑 | G16: 入口、触发、输入输出、状态变化、反馈、验收是否可执行？ | H16: 流程、状态机、反馈、验收、自测
A17: 检查层级 | B17: 适用项 | C17: 通过项 | D17: 通过率 | F17: 信息准确 | G17: 事实、假设、待确认项、数据口径、系统能力是否区分？ | H17: 数据来源、统计口径、待确认、能力边界
A18: 必查门禁 | B18: =COUNTIFS('01_需求自查清单'!$B$2:$B$200,A18,'01_需求自查清单'!$N$2:$N$200,"是") -> 21 | C18: =COUNTIFS('01_需求自查清单'!$B$2:$B$200,A18,'01_需求自查清单'!$N$2:$N$200,"是",'01_需求自查清单'!$R$2:$R$200,"通过") -> 0 | D18: =IF(B18=0,0,C18/B18) -> 0
A19: 扩展检查 | B19: =COUNTIFS('01_需求自查清单'!$B$2:$B$200,A19,'01_需求自查清单'!$N$2:$N$200,"是") -> 39 | C19: =COUNTIFS('01_需求自查清单'!$B$2:$B$200,A19,'01_需求自查清单'!$N$2:$N$200,"是",'01_需求自查清单'!$R$2:$R$200,"通过") -> 0 | D19: =IF(B19=0,0,C19/B19) -> 0
A20: 优化建议 | B20: =COUNTIFS('01_需求自查清单'!$B$2:$B$200,A20,'01_需求自查清单'!$N$2:$N$200,"是") -> 6 | C20: =COUNTIFS('01_需求自查清单'!$B$2:$B$200,A20,'01_需求自查清单'!$N$2:$N$200,"是",'01_需求自查清单'!$R$2:$R$200,"通过") -> 0 | D20: =IF(B20=0,0,C20/B20) -> 0 | F20: 使用顺序
F21: 1. 先在 01_需求自查清单 中按需求复杂度调整“是否适用”
F22: 2. 对适用项填写“是否已写”“是否已检查”“PRD证据位置”
F23: 3. 若部分覆盖，填写“部分”，门禁状态会进入“待补充”
F24: 4. 若未覆盖，按默认优先级自动生成 P0阻塞 / P1风险 / 建议优化
F25: 5. 回到本看板查看 P0/P1 是否清零，再决定能否进入评审
A27: 模板补充提醒｜根据“建议呈现方式”和门禁状态，提示应优先补哪类表
A28: 模板类型 | B28: 需补项数 | C28: 统计逻辑 | D28: 模板位置
A29: 规则表 | B29: =COUNTIFS('01_需求自查清单'!$K:$K,"*规则表*",'01_需求自查清单'!$N:$N,"是",'01_需求自查清单'!$R:$R,"<>通过",'01_需求自查清单'!$R:$R,"<>不适用") -> 22 | C29: 建议呈现方式包含“规则表”且未通过/待补充/P0/P1/建议优化 | D29: 07_表格模板示例!A14
A30: 字段规则表 | B30: =COUNTIFS('01_需求自查清单'!$K:$K,"*字段规则表*",'01_需求自查清单'!$N:$N,"是",'01_需求自查清单'!$R:$R,"<>通过",'01_需求自查清单'!$R:$R,"<>不适用") -> 2 | C30: 建议呈现方式包含“字段规则表”且未通过/待补充/P0/P1/建议优化 | D30: 07_表格模板示例!A34
A31: 校验规则表 | B31: =COUNTIFS('01_需求自查清单'!$K:$K,"*校验规则表*",'01_需求自查清单'!$N:$N,"是",'01_需求自查清单'!$R:$R,"<>通过",'01_需求自查清单'!$R:$R,"<>不适用") -> 2 | C31: 建议呈现方式包含“校验规则表”且未通过/待补充/P0/P1/建议优化 | D31: 07_表格模板示例!A54
A32: 数据口径表 | B32: =COUNTIFS('01_需求自查清单'!$K:$K,"*数据口径表*",'01_需求自查清单'!$N:$N,"是",'01_需求自查清单'!$R:$R,"<>通过",'01_需求自查清单'!$R:$R,"<>不适用") -> 0 | C32: 建议呈现方式包含“数据口径表”且未通过/待补充/P0/P1/建议优化 | D32: 07_表格模板示例!A74
A33: 异常规则表 | B33: =COUNTIFS('01_需求自查清单'!$K:$K,"*异常规则表*",'01_需求自查清单'!$N:$N,"是",'01_需求自查清单'!$R:$R,"<>通过",'01_需求自查清单'!$R:$R,"<>不适用") -> 1 | C33: 建议呈现方式包含“异常规则表”且未通过/待补充/P0/P1/建议优化 | D33: 07_表格模板示例!A94
A34: 验收标准表 | B34: =COUNTIFS('01_需求自查清单'!$K:$K,"*验收标准表*",'01_需求自查清单'!$N:$N,"是",'01_需求自查清单'!$R:$R,"<>通过",'01_需求自查清单'!$R:$R,"<>不适用") -> 1 | C34: 建议呈现方式包含“验收标准表”且未通过/待补充/P0/P1/建议优化 | D34: 07_表格模板示例!A116
A35: 自测用例表 | B35: =COUNTIFS('01_需求自查清单'!$K:$K,"*自测用例表*",'01_需求自查清单'!$N:$N,"是",'01_需求自查清单'!$R:$R,"<>通过",'01_需求自查清单'!$R:$R,"<>不适用") -> 1 | C35: 建议呈现方式包含“自测用例表”且未通过/待补充/P0/P1/建议优化 | D35: 07_表格模板示例!A135
A36: 风险接受表 | B36: =COUNTIFS('01_需求自查清单'!$K:$K,"*风险接受表*",'01_需求自查清单'!$N:$N,"是",'01_需求自查清单'!$R:$R,"<>通过",'01_需求自查清单'!$R:$R,"<>不适用") -> 1 | C36: 建议呈现方式包含“风险接受表”且未通过/待补充/P0/P1/建议优化 | D36: 07_表格模板示例!A154

Sheet 01_需求自查清单
A1: 序号 | B1: 检查层级 | C1: 一级检查域 | D1: 二级模块 | E1: 检查项 | F1: 适用条件 | G1: 自查问题 | H1: 合格标准 | I1: 不通过信号 | J1: 建议补充位置 | K1: 建议呈现方式 | L1: 默认优先级 | M1: 复杂度适配 | N1: 是否适用 | O1: 是否已写 | P1: 是否已检查 | Q1: 实际问题等级 | R1: 门禁状态 | S1: 修正动作 | T1: PRD证据位置 | U1: 备注 | V1: 模板位置
A2: 1 | B2: 必查门禁 | C2: 需求定义与复杂度判断 | D2: 真实问题 | E2: 真实问题是否明确 | F2: 所有需求 | G2: 是否写清楚解决谁的什么问题，而不是只复述一个功能方案？ | H2: 能明确用户/角色、现状问题、痛点后果、为什么现在要做；读者能复述需求的业务价值。 | I2: 只写“新增某功能”“优化某页面”“支持某配置”，没有说明真实问题。 | J2: 为什么做 / 背景与真实问题 | K2: SCQA说明 / 问题定义表 | L2: P0 | M2: L1-L4 | N2: 是 | R2: =IF(N2="否","不适用",IF(N2<>"是","待判断",IF(AND(O2="是",P2="是"),"通过",IF(O2="部分","待补充",IF(AND(O2="否",L2="P0"),"P0阻塞",IF(AND(O2="否",L2="P1"),"P1风险",IF(O2="否","建议优化","待检查"))))))) -> 待检查 | S2: 补充问题定义：用户、场景、痛点、现状、为什么现在做。
A3: 2 | B3: 必查门禁 | C3: 需求定义与复杂度判断 | D3: 本期目标 | E3: 本期目标与成功标准 | F3: 所有需求 | G3: 是否写清本期做到什么程度算有效？ | H3: 有可判断的目标或成功标准，能说明做完后业务或流程会发生什么变化。 | I3: 只写“提升效率”“优化体验”“完善管理”，没有可验证结果。 | J3: 为什么做 / 产品目标与成功标准 | K3: 目标表 / 成功标准表 | L3: P0 | M3: L1-L4 | N3: 是 | R3: =IF(N3="否","不适用",IF(N3<>"是","待判断",IF(AND(O3="是",P3="是"),"通过",IF(O3="部分","待补充",IF(AND(O3="否",L3="P0"),"P0阻塞",IF(AND(O3="否",L3="P2"),"P2风险",IF(O3="否","建议优化","待检查"))))))) -> 待检查 | S3: 补充本期目标和可验证成功标准。
A4: 3 | B4: 必查门禁 | C4: 需求定义与复杂度判断 | D4: 适用端范围 | E4: 需求涉及端范围 | F4: 涉及多个端或入口时必查 | G4: 是否写清需求适用哪些端，哪些端不适用？ | H4: 平台、PC、APP、小程序、公众号、管理后台等范围明确，端之间差异明确。 | I4: 只写“系统支持”，但不知道在哪些端支持。 | J4: 是什么 / 需求范围 | K4: 范围表 | L4: P0 | M4: L1-L4 | N4: 是 | R4: =IF(N4="否","不适用",IF(N4<>"是","待判断",IF(AND(O4="是",P4="是"),"通过",IF(O4="部分","待补充",IF(AND(O4="否",L4="P0"),"P0阻塞",IF(AND(O4="否",L4="P3"),"P3风险",IF(O4="否","建议优化","待检查"))))))) -> 待检查 | S4: 补充适用端、入口、端间差异和排除端。
A5: 4 | B5: 必查门禁 | C5: 边界清晰检查 | D5: 本期范围 | E5: 本期做什么 | F5: 所有需求 | G5: 本期具体包含哪些功能、场景、角色、数据？ | H5: 功能边界、角色边界、场景边界、数据边界可被研发和测试直接识别。 | I5: 只写功能点，不写边界；读者仍会问“这个本期做不做”。 | J5: 为什么做 / 范围与优先级 | K5: 范围表 | L5: P0 | M5: L1-L4 | N5: 是 | R5: =IF(N5="否","不适用",IF(N5<>"是","待判断",IF(AND(O5="是",P5="是"),"通过",IF(O5="部分","待补充",IF(AND(O5="否",L5="P0"),"P0阻塞",IF(AND(O5="否",L5="P4"),"P4风险",IF(O5="否","建议优化","待检查"))))))) -> 待检查 | S5: 补充本期范围表：功能、角色、场景、数据、优先级。
A6: 5 | B6: 必查门禁 | C6: 边界清晰检查 | D6: 非目标 | E6: 本期不做什么 | F6: L2及以上需求；存在范围误解风险时必查 | G6: 哪些容易被误认为本期要做的内容已被明确排除？ | H6: 有非目标表，且排除项明确；后续规划与本期范围分离。 | I6: 后续想法混入本期；没有说明暂不覆盖的角色、数据或场景。 | J6: 为什么做 / 本期不做 | K6: 非目标表 | L6: P0 | M6: L2-L4 | N6: 是 | R6: =IF(N6="否","不适用",IF(N6<>"是","待判断",IF(AND(O6="是",P6="是"),"通过",IF(O6="部分","待补充",IF(AND(O6="否",L6="P0"),"P0阻塞",IF(AND(O6="否",L6="P5"),"P5风险",IF(O6="否","建议优化","待检查"))))))) -> 待检查 | S6: 补充非目标表，写明排除原因和是否进入后续规划。
A7: 6 | B7: 必查门禁 | C7: 边界清晰检查 | D7: 角色边界 | E7: 角色与职责边界 | F7: 多角色、B端、审批、配置、维护类需求 | G7: 谁使用、谁配置、谁审批、谁维护、谁处理异常？ | H7: 角色名称、职责、参与环节清楚；角色之间不重叠、不混用。 | I7: 使用“相关人员”“管理员”等泛称，未定义具体角色。 | J7: 是什么 / 角色与权限 | K7: 角色职责表 | L7: P0 | M7: L2-L4 | N7: 是 | R7: =IF(N7="否","不适用",IF(N7<>"是","待判断",IF(AND(O7="是",P7="是"),"通过",IF(O7="部分","待补充",IF(AND(O7="否",L7="P0"),"P0阻塞",IF(AND(O7="否",L7="P6"),"P6风险",IF(O7="否","建议优化","待检查"))))))) -> 待检查 | S7: 补充角色职责表，统一角色命名。
A8: 7 | B8: 必查门禁 | C8: 边界清晰检查 | D8: 权限边界 | E8: 角色权限矩阵 | F8: 存在查看、新增、编辑、删除、审批、配置等权限差异时必查 | G8: 不同角色能看什么、做什么、不能做什么？ | H8: 有角色权限矩阵，覆盖页面入口、数据范围、操作按钮和异常无权限反馈。 | I8: 只写“有权限的人可操作”，没有权限来源和限制。 | J8: 是什么 / 角色权限矩阵 | K8: 权限矩阵 | L8: P0 | M8: L2-L4 | N8: 是 | R8: =IF(N8="否","不适用",IF(N8<>"是","待判断",IF(AND(O8="是",P8="是"),"通过",IF(O8="部分","待补充",IF(AND(O8="否",L8="P0"),"P0阻塞",IF(AND(O8="否",L8="P7"),"P7风险",IF(O8="否","建议优化","待检查"))))))) -> 待检查 | S8: 补充角色×操作×数据范围×状态的权限矩阵。
A9: 8 | B9: 必查门禁 | C9: 不留猜疑检查 | D9: 主流程 | E9: 主流程闭环 | F9: L2及以上需求 | G9: 主流程能否从入口、操作、系统处理、结果反馈一直走到结束？ | H9: 有入口、触发条件、操作步骤、系统处理、结果反馈、结束状态；流程可执行。 | I9: 流程只写到“提交/保存”，未写提交后发生什么。 | J9: 是什么 / 主流程 | K9: 流程图 + 步骤表 | L9: P0 | M9: L2-L4 | N9: 是 | R9: =IF(N9="否","不适用",IF(N9<>"是","待判断",IF(AND(O9="是",P9="是"),"通过",IF(O9="部分","待补充",IF(AND(O9="否",L9="P0"),"P0阻塞",IF(AND(O9="否",L9="P8"),"P8风险",IF(O9="否","建议优化","待检查"))))))) -> 待检查 | S9: 补充主流程图，并在步骤表中写清用户动作和系统响应。
A10: 9 | B10: 必查门禁 | C10: 不留猜疑检查 | D10: 分支流程 | E10: 分支、逆向与退出路径 | F10: 存在审批、撤回、驳回、取消、删除、关闭、终止等动作时必查 | G10: 逆向流程、退出流程、失败流程是否写清？ | H10: 撤回、驳回、取消、失败、关闭、超时等路径有触发条件、结果和状态变化。 | I10: 只有正向流程；用户取消、失败、撤回后结果不明。 | J10: 是什么 / 流程与状态变化 | K10: 流程图 + 规则表 | L10: P0 | M10: L2-L4 | N10: 是 | R10: =IF(N10="否","不适用",IF(N10<>"是","待判断",IF(AND(O10="是",P10="是"),"通过",IF(O10="部分","待补充",IF(AND(O10="否",L10="P0"),"P0阻塞",IF(AND(O10="否",L10="P9"),"P9风险",IF(O10="否","建议优化","待检查"))))))) -> 待检查 | S10: 补充分支/逆向流程，明确每条路径的结束状态。 | V10: 07_表格模板示例!A14｜规则表模板
A11: 10 | B11: 必查门禁 | C11: 不留猜疑检查 | D11: 状态机 | E11: 状态及状态变更 | F11: 存在启停、审批、发布、关闭、驳回、作废、流转等状态变化时必查 | G11: 所有状态、触发动作、操作角色、前置状态、目标状态是否完整？ | H11: 状态机图或状态流转表覆盖主流程、逆向流程、异常流程；每个状态均有可执行动作和下一状态。 | I11: 只列“待审批、已审批、已驳回”等状态名称，没写触发条件和可操作动作。 | J11: 是什么 / 状态机模型 | K11: 状态机图 + 状态流转表 | L11: P0 | M11: L2-L4 | N11: 是 | R11: =IF(N11="否","不适用",IF(N11<>"是","待判断",IF(AND(O11="是",P11="是"),"通过",IF(O11="部分","待补充",IF(AND(O11="否",L11="P0"),"P0阻塞",IF(AND(O11="否",L11="P10"),"P10风险",IF(O11="否","建议优化","待检查"))))))) -> 待检查 | S11: 补状态机图；无法确认的状态进入待确认事项。
A12: 11 | B12: 必查门禁 | C12: 判断显性检查 | D12: 核心规则 | E12: 核心业务规则 | F12: L2及以上需求 | G12: 什么条件下允许、禁止、触发、关闭、变更？ | H12: 每个核心功能都有规则、触发条件、限制条件、默认处理和责任方。 | I12: 只写“支持配置”“支持审批”“支持查询”，无条件、规则和结果。 | J12: 是什么 / 功能规则 | K12: 业务规则表 | L12: P0 | M12: L2-L4 | N12: 是 | R12: =IF(N12="否","不适用",IF(N12<>"是","待判断",IF(AND(O12="是",P12="是"),"通过",IF(O12="部分","待补充",IF(AND(O12="否",L12="P0"),"P0阻塞",IF(AND(O12="否",L12="P11"),"P11风险",IF(O12="否","建议优化","待检查"))))))) -> 待检查 | S12: 补核心规则表，按功能域写清条件、动作、结果。 | V12: 07_表格模板示例!A14｜规则表模板
A13: 12 | B13: 必查门禁 | C13: 判断显性检查 | D13: 默认规则 | E13: 关键默认值 | F13: 存在默认筛选、默认排序、默认状态、默认开关、默认人员时必查 | G13: 用户不操作时，系统默认怎么处理？ | H13: 默认值、默认状态、默认排序、默认筛选、默认开关均明确；默认来源清楚。 | I13: 默认值交给研发猜；只在原型里出现但PRD不写。 | J13: 是什么 / 默认规则 | K13: 默认值表 | L13: P0 | M13: L1-L4 | N13: 是 | R13: =IF(N13="否","不适用",IF(N13<>"是","待判断",IF(AND(O13="是",P13="是"),"通过",IF(O13="部分","待补充",IF(AND(O13="否",L13="P0"),"P0阻塞",IF(AND(O13="否",L13="P12"),"P12风险",IF(O13="否","建议优化","待检查"))))))) -> 待检查 | S13: 补默认值表，区分系统默认、角色默认、历史记忆和配置默认。
A14: 13 | B14: 必查门禁 | C14: 判断显性检查 | D14: 操作控制 | E14: 按钮与操作控制 | F14: 有按钮、菜单、批量操作、行内操作时必查 | G14: 不同角色、不同状态下按钮是否可见、可点、禁用？ | H14: 有操作控制表，覆盖显示条件、可点条件、禁用原因、点击结果。 | I14: 只画按钮，不写状态限制；测试不知道哪些情况下按钮应禁用。 | J14: 是什么 / 操作规则 | K14: 操作控制表 | L14: P0 | M14: L2-L4 | N14: 是 | R14: =IF(N14="否","不适用",IF(N14<>"是","待判断",IF(AND(O14="是",P14="是"),"通过",IF(O14="部分","待补充",IF(AND(O14="否",L14="P0"),"P0阻塞",IF(AND(O14="否",L14="P13"),"P13风险",IF(O14="否","建议优化","待检查"))))))) -> 待检查 | S14: 补角色×状态×按钮的操作控制表。
A15: 14 | B15: 必查门禁 | C15: 信息准确检查 | D15: 数据来源 | E15: 数据来源与更新时间 | F15: 涉及业务数据、列表、统计、报表、外部系统时必查 | G15: 数据从哪里来？什么时候更新？是否同步或延迟？ | H15: 数据来源、更新时间、同步方式、数据延迟、异常兜底明确。 | I15: 写了“展示数据”，但没有说明来源、口径或更新时间。 | J15: 是什么 / 数据说明 | K15: 数据来源表 | L15: P1 | M15: L2-L4 | N15: 是 | R15: =IF(N15="否","不适用",IF(N15<>"是","待判断",IF(AND(O15="是",P15="是"),"通过",IF(O15="部分","待补充",IF(AND(O15="否",L15="P0"),"P0阻塞",IF(AND(O15="否",L15="P14"),"P14风险",IF(O15="否","建议优化","待检查"))))))) -> 待检查 | S15: 补数据来源、更新频率、同步失败兜底。
A16: 15 | B16: 必查门禁 | C16: 信息准确检查 | D16: 统计口径 | E16: 指标与统计口径 | F16: 涉及指标、报表、看板、排名、百分比时必查 | G16: 指标怎么算？统计范围、时间范围、筛选条件是什么？ | H16: 有指标定义、计算口径、单位、时间范围、过滤条件和边界说明。 | I16: 数字有了，算法没有；报表口径和列表口径可能不一致。 | J16: 是什么 / 数据口径 | K16: 统计口径表 | L16: P1 | M16: L3-L4 | N16: 是 | R16: =IF(N16="否","不适用",IF(N16<>"是","待判断",IF(AND(O16="是",P16="是"),"通过",IF(O16="部分","待补充",IF(AND(O16="否",L16="P0"),"P0阻塞",IF(AND(O16="否",L16="P15"),"P15风险",IF(O16="否","建议优化","待检查"))))))) -> 待检查 | S16: 补统计口径表：指标、公式、范围、单位、更新时间。
A17: 16 | B17: 必查门禁 | C17: 判断显性检查 | D17: 异常兜底 | E17: 空态、失败、重复、冲突、权限不足 | F17: L2及以上需求 | G17: 空态、失败、重复、冲突、权限不足等情况怎么处理？ | H17: 核心异常均有触发条件、系统处理、用户提示、是否可重试/恢复说明。 | I17: 只有正常流程；失败、无数据、无权限、重复提交均未定义。 | J17: 怎么玩 / 异常与兜底 | K17: 异常规则表 | L17: P0 | M17: L2-L4 | N17: 是 | R17: =IF(N17="否","不适用",IF(N17<>"是","待判断",IF(AND(O17="是",P17="是"),"通过",IF(O17="部分","待补充",IF(AND(O17="否",L17="P0"),"P0阻塞",IF(AND(O17="否",L17="P16"),"P16风险",IF(O17="否","建议优化","待检查"))))))) -> 待检查 | S17: 补异常规则表，至少覆盖空态、失败、重复、冲突、权限不足。 | V17: 07_表格模板示例!A94｜异常规则表模板；07_表格模板示例!A14｜规则表模板
A18: 17 | B18: 必查门禁 | C18: 不留猜疑检查 | D18: 结果反馈 | E18: 操作结果反馈 | F18: 有提交、保存、审批、删除、启停、批量处理等动作时必查 | G18: 成功、失败、处理中分别如何反馈？页面和数据如何变化？ | H18: 明确点击前、中、后的页面状态、提示、刷新、跳转、数据变化。 | I18: 点完以后发生什么没写；成功后是否关闭弹窗、是否刷新列表不明。 | J18: 怎么玩 / 交互反馈 | K18: 反馈规则表 | L18: P1 | M18: L2-L4 | N18: 是 | R18: =IF(N18="否","不适用",IF(N18<>"是","待判断",IF(AND(O18="是",P18="是"),"通过",IF(O18="部分","待补充",IF(AND(O18="否",L18="P0"),"P0阻塞",IF(AND(O18="否",L18="P17"),"P17风险",IF(O18="否","建议优化","待检查"))))))) -> 待检查 | S18: 补操作反馈规则表，写清成功、失败、处理中。 | V18: 07_表格模板示例!A14｜规则表模板
A19: 18 | B19: 必查门禁 | C19: 信息准确检查 | D19: 待确认事项 | E19: 假设与待确认项 | F19: 存在未确认规则、数据、依赖、范围、外部接口时必查 | G19: 未确认内容是否明确标记，而不是写成确定事实？ | H19: 有待确认事项表，说明影响范围、负责人、确认时点；不影响核心判断的才允许挂起。 | I19: 把假设写成事实；未确认内容直接进入开发依据。 | J19: 附录 / 待确认事项 | K19: 待确认事项表 | L19: P0 | M19: L1-L4 | N19: 是 | R19: =IF(N19="否","不适用",IF(N19<>"是","待判断",IF(AND(O19="是",P19="是"),"通过",IF(O19="部分","待补充",IF(AND(O19="否",L19="P0"),"P0阻塞",IF(AND(O19="否",L19="P18"),"P18风险",IF(O19="否","建议优化","待检查"))))))) -> 待检查 | S19: 补待确认事项表；影响P0/P1判断的事项必须先确认。
A20: 19 | B20: 必查门禁 | C20: 不留猜疑检查 | D20: 验收标准 | E20: 可验证验收 | F20: 所有需求 | G20: 怎么判断做完且做对？ | H20: 验收项可测试、可观察、可判断；覆盖主流程、核心规则、异常、权限和数据。 | I20: 只写“功能正常即可”“符合需求即可”。 | J20: 怎么玩 / 验收标准 | K20: 验收标准表 | L20: P0 | M20: L1-L4 | N20: 是 | R20: =IF(N20="否","不适用",IF(N20<>"是","待判断",IF(AND(O20="是",P20="是"),"通过",IF(O20="部分","待补充",IF(AND(O20="否",L20="P0"),"P0阻塞",IF(AND(O20="否",L20="P19"),"P19风险",IF(O20="否","建议优化","待检查"))))))) -> 待检查 | S20: 补验收标准，使用可观察、可测试的判定句。 | V20: 07_表格模板示例!A116｜验收标准表模板
A21: 20 | B21: 必查门禁 | C21: 不留猜疑检查 | D21: 研发自测 | E21: 最小自测用例 | F21: L2及以上需求 | G21: 研发交付前至少跑哪些自测用例？ | H21: 主流程、异常、权限、数据边界有最小用例；可用于交付前冒烟检查。 | I21: 只有测试阶段才发现主流程不通。 | J21: 怎么玩 / 研发自测用例 | K21: 自测用例表 | L21: P1 | M21: L2-L4 | N21: 是 | R21: =IF(N21="否","不适用",IF(N21<>"是","待判断",IF(AND(O21="是",P21="是"),"通过",IF(O21="部分","待补充",IF(AND(O21="否",L21="P0"),"P0阻塞",IF(AND(O21="否",L21="P20"),"P20风险",IF(O21="否","建议优化","待检查"))))))) -> 待检查 | S21: 补最小自测用例，覆盖主线、逆向、异常、权限。 | V21: 07_表格模板示例!A135｜自测用例表模板
A22: 21 | B22: 必查门禁 | C22: 阻塞问题与评审结论 | D22: 评审结论 | E22: P0/P1阻塞判断 | F22: 所有需求 | G22: 是否存在未处理的P0/P1问题？是否可进入评审？ | H22: P0清零；P1已修正或记录风险接受；评审结论明确。 | I22: 带着P0进入评审；P1未说明是否接受风险。 | J22: 评审结论 / 阻塞项清单 | K22: 评审结论卡 | L22: P0 | M22: L1-L4 | N22: 是 | R22: =IF(N22="否","不适用",IF(N22<>"是","待判断",IF(AND(O22="是",P22="是"),"通过",IF(O22="部分","待补充",IF(AND(O22="否",L22="P0"),"P0阻塞",IF(AND(O22="否",L22="P21"),"P21风险",IF(O22="否","建议优化","待检查"))))))) -> 待检查 | S22: 输出阻塞项清单和评审结论。
A23: 22 | B23: 扩展检查 | C23: 页面、表单与数据展示检查 | D23: 文本输入 | E23: 文本输入规则 | F23: 有文本框、名称、标题、备注、说明等字段 | G23: 是否写清长度、格式、特殊字符、空格、重复规则？ | H23: 字段长度、格式、字符限制、空格处理、重复处理和提示文案明确。 | I23: 只写“输入名称/备注”，没有长度和格式限制。 | J23: 是什么 / 表单字段规则 | K23: 字段规则表 | L23: P1 | M23: L1-L4 | N23: 是 | R23: =IF(N23="否","不适用",IF(N23<>"是","待判断",IF(AND(O23="是",P23="是"),"通过",IF(O23="部分","待补充",IF(AND(O23="否",L23="P0"),"P0阻塞",IF(AND(O23="否",L23="P22"),"P22风险",IF(O23="否","建议优化","待检查"))))))) -> 待检查 | S23: 补字段规则表。 | V23: 07_表格模板示例!A34｜字段规则表模板；07_表格模板示例!A14｜规则表模板
A24: 23 | B24: 扩展检查 | C24: 页面、表单与数据展示检查 | D24: 必填校验 | E24: 必填项与校验时机 | F24: 有新增、编辑、提交、审批表单 | G24: 哪些字段必填？何时校验？失败提示什么？ | H24: 必填字段、校验时机、失败提示、是否支持暂存明确。 | I24: 表单字段很多，但哪些必填不清；保存和提交校验不区分。 | J24: 是什么 / 表单校验 | K24: 校验规则表 | L24: P0 | M24: L1-L4 | N24: 是 | R24: =IF(N24="否","不适用",IF(N24<>"是","待判断",IF(AND(O24="是",P24="是"),"通过",IF(O24="部分","待补充",IF(AND(O24="否",L24="P0"),"P0阻塞",IF(AND(O24="否",L24="P23"),"P23风险",IF(O24="否","建议优化","待检查"))))))) -> 待检查 | S24: 补必填校验表，区分保存、提交、审批等时机。 | V24: 07_表格模板示例!A54｜校验规则表模板；07_表格模板示例!A14｜规则表模板
A25: 24 | B25: 扩展检查 | C25: 页面、表单与数据展示检查 | D25: 重复校验 | E25: 重复数据校验 | F25: 名称、编码、模板、配置、规则等可能重复 | G25: 按哪个字段查重？查重范围是什么？重复后怎么处理？ | H25: 查重字段、查重范围、大小写/空格处理、重复提示、是否允许覆盖明确。 | I25: 只写“名称不可重复”，没有说明按组织、模块还是全局查重。 | J25: 是什么 / 表单校验 | K25: 校验规则表 | L25: P1 | M25: L1-L4 | N25: 是 | R25: =IF(N25="否","不适用",IF(N25<>"是","待判断",IF(AND(O25="是",P25="是"),"通过",IF(O25="部分","待补充",IF(AND(O25="否",L25="P0"),"P0阻塞",IF(AND(O25="否",L25="P24"),"P24风险",IF(O25="否","建议优化","待检查"))))))) -> 待检查 | S25: 补重复校验规则。 | V25: 07_表格模板示例!A54｜校验规则表模板；07_表格模板示例!A14｜规则表模板
A26: 25 | B26: 扩展检查 | C26: 页面、表单与数据展示检查 | D26: 文件上传 | E26: 文件/图片上传规则 | F26: 有文件、图片、附件、导入模板上传 | G26: 支持什么格式、大小、数量？失败后如何处理？ | H26: 格式、大小、数量、失败处理、删除重传、预览/下载规则明确。 | I26: 只写“支持上传附件”。 | J26: 是什么 / 上传规则 | K26: 上传规则表 | L26: P1 | M26: L2-L4 | N26: 是 | R26: =IF(N26="否","不适用",IF(N26<>"是","待判断",IF(AND(O26="是",P26="是"),"通过",IF(O26="部分","待补充",IF(AND(O26="否",L26="P0"),"P0阻塞",IF(AND(O26="否",L26="P25"),"P25风险",IF(O26="否","建议优化","待检查"))))))) -> 待检查 | S26: 补上传规则表。 | V26: 07_表格模板示例!A14｜规则表模板
A27: 26 | B27: 扩展检查 | C27: 页面、表单与数据展示检查 | D27: 时间控件 | E27: 时间精度与范围 | F27: 有日期、时间、周期、有效期、截止时间 | G27: 时间精确到年/月/日/时/分/秒？默认值和可选范围是什么？ | H27: 时间精度、默认值、可选范围、跨天/跨月/跨年、开始结束校验明确。 | I27: 时间精度不明；开始时间可晚于结束时间。 | J27: 是什么 / 字段规则 | K27: 字段规则表 | L27: P1 | M27: L1-L4 | N27: 是 | R27: =IF(N27="否","不适用",IF(N27<>"是","待判断",IF(AND(O27="是",P27="是"),"通过",IF(O27="部分","待补充",IF(AND(O27="否",L27="P0"),"P0阻塞",IF(AND(O27="否",L27="P26"),"P26风险",IF(O27="否","建议优化","待检查"))))))) -> 待检查 | S27: 补时间控件规则。 | V27: 07_表格模板示例!A34｜字段规则表模板；07_表格模板示例!A14｜规则表模板
A28: 27 | B28: 扩展检查 | C28: 页面、表单与数据展示检查 | D28: 选择控件 | E28: 单选/复选/下拉规则 | F28: 有单选、复选、下拉、标签选择、弹窗选择 | G28: 默认值、是否可清空、选项来源、禁用项、排序规则是什么？ | H28: 默认值、选项来源、是否支持搜索/多选/清空、禁用项和回显规则明确。 | I28: 只写“选择类型”，选项从哪来不明。 | J28: 是什么 / 控件规则 | K28: 控件规则表 | L28: P1 | M28: L1-L4 | N28: 是 | R28: =IF(N28="否","不适用",IF(N28<>"是","待判断",IF(AND(O28="是",P28="是"),"通过",IF(O28="部分","待补充",IF(AND(O28="否",L28="P0"),"P0阻塞",IF(AND(O28="否",L28="P27"),"P27风险",IF(O28="否","建议优化","待检查"))))))) -> 待检查 | S28: 补选择控件规则表。 | V28: 07_表格模板示例!A14｜规则表模板
A29: 28 | B29: 扩展检查 | C29: 页面、表单与数据展示检查 | D29: 多组数据 | E29: 多行/多组/多标签数量控制 | F29: 支持添加多行、多组、多标签、多附件 | G29: 最多能添加几组？能否删除、排序、重复？超出怎么提示？ | H29: 最大数量、最小数量、删除规则、排序规则、重复规则、超限提示明确。 | I29: 能无限添加但没说明上限；重复选择后结果不明。 | J29: 是什么 / 数量规则 | K29: 数量规则表 | L29: P2 | M29: L2-L4 | N29: 是 | R29: =IF(N29="否","不适用",IF(N29<>"是","待判断",IF(AND(O29="是",P29="是"),"通过",IF(O29="部分","待补充",IF(AND(O29="否",L29="P0"),"P0阻塞",IF(AND(O29="否",L29="P28"),"P28风险",IF(O29="否","建议优化","待检查"))))))) -> 待检查 | S29: 补多组数据规则。 | V29: 07_表格模板示例!A14｜规则表模板
A30: 29 | B30: 扩展检查 | C30: 页面、表单与数据展示检查 | D30: 字段状态 | E30: 字段可编辑/只读/禁用 | F30: 有自动带出、系统生成、只读、禁用、输出字段 | G30: 哪些字段可编辑、只读、禁用、自动生成、仅展示？ | H30: 每个字段的输入/输出/禁用/只读状态明确，并说明状态变化条件。 | I30: 字段展示了，但不知道能不能改。 | J30: 是什么 / 表单字段总览 | K30: 字段总表 | L30: P1 | M30: L1-L4 | N30: 是 | R30: =IF(N30="否","不适用",IF(N30<>"是","待判断",IF(AND(O30="是",P30="是"),"通过",IF(O30="部分","待补充",IF(AND(O30="否",L30="P0"),"P0阻塞",IF(AND(O30="否",L30="P29"),"P29风险",IF(O30="否","建议优化","待检查"))))))) -> 待检查 | S30: 补字段总表，加入字段状态列。
A31: 30 | B31: 扩展检查 | C31: 列表查询与数据展示检查 | D31: 列表字段 | E31: 列表字段总览 | F31: 有列表或表格 | G31: 字段名、含义、来源、展示规则、空值展示是否明确？ | H31: 一个表格说明字段名、字段含义、来源、展示规则、空值规则、是否排序/筛选。 | I31: 字段散写在段落里，研发和测试难以核对。 | J31: 是什么 / 列表字段总览 | K31: 表格字段总览 | L31: P1 | M31: L1-L4 | N31: 是 | R31: =IF(N31="否","不适用",IF(N31<>"是","待判断",IF(AND(O31="是",P31="是"),"通过",IF(O31="部分","待补充",IF(AND(O31="否",L31="P0"),"P0阻塞",IF(AND(O31="否",L31="P30"),"P30风险",IF(O31="否","建议优化","待检查"))))))) -> 待检查 | S31: 补列表字段总览表。
A32: 31 | B32: 扩展检查 | C32: 列表查询与数据展示检查 | D32: 默认排序 | E32: 列表默认排序 | F32: 有列表、记录、日志、模板库 | G32: 默认按哪个字段排序？升序还是降序？空值如何处理？ | H32: 默认排序字段、排序方向、空值排序、同值次序明确。 | I32: 列表顺序不明；不同端排序不一致。 | J32: 是什么 / 列表规则 | K32: 排序规则表 | L32: P1 | M32: L1-L4 | N32: 是 | R32: =IF(N32="否","不适用",IF(N32<>"是","待判断",IF(AND(O32="是",P32="是"),"通过",IF(O32="部分","待补充",IF(AND(O32="否",L32="P0"),"P0阻塞",IF(AND(O32="否",L32="P31"),"P31风险",IF(O32="否","建议优化","待检查"))))))) -> 待检查 | S32: 补默认排序规则。 | V32: 07_表格模板示例!A14｜规则表模板
A33: 32 | B33: 扩展检查 | C33: 列表查询与数据展示检查 | D33: 超长展示 | E33: 长文本展示规则 | F33: 有名称、标题、备注、正文、地址等长文本 | G33: 超过多少字符省略？是否悬浮、展开或进入详情？ | H33: 截断长度、展示方式、悬浮/展开/详情入口、移动端适配明确。 | I33: 超长后页面怎么展示不明；重要信息被截断无法查看。 | J33: 是什么 / 展示规则 | K33: 展示规则表 | L33: P2 | M33: L1-L4 | N33: 是 | R33: =IF(N33="否","不适用",IF(N33<>"是","待判断",IF(AND(O33="是",P33="是"),"通过",IF(O33="部分","待补充",IF(AND(O33="否",L33="P0"),"P0阻塞",IF(AND(O33="否",L33="P32"),"P32风险",IF(O33="否","建议优化","待检查"))))))) -> 待检查 | S33: 补超长展示规则。 | V33: 07_表格模板示例!A14｜规则表模板
A34: 33 | B34: 扩展检查 | C34: 列表查询与数据展示检查 | D34: 查询条件 | E34: 查询默认值与重置 | F34: 有筛选区、搜索框、标签筛选 | G34: 默认查询什么？重置后回到什么状态？精准还是模糊？ | H34: 查询类型、默认值、重置规则、空查询、查询按钮触发方式明确。 | I34: 筛选项有了，但查询逻辑不清。 | J34: 是什么 / 查询规则 | K34: 查询规则表 | L34: P1 | M34: L1-L4 | N34: 是 | R34: =IF(N34="否","不适用",IF(N34<>"是","待判断",IF(AND(O34="是",P34="是"),"通过",IF(O34="部分","待补充",IF(AND(O34="否",L34="P0"),"P0阻塞",IF(AND(O34="否",L34="P33"),"P33风险",IF(O34="否","建议优化","待检查"))))))) -> 待检查 | S34: 补查询规则，区分精准筛选和模糊筛选。 | V34: 07_表格模板示例!A14｜规则表模板
A35: 34 | B35: 扩展检查 | C35: 列表查询与数据展示检查 | D35: 查询联动 | E35: 查询条件联动/互斥 | F35: 筛选条件之间有关联、层级、互斥或冲突 | G35: 条件之间如何联动？冲突时哪个条件优先？ | H35: 父子联动、互斥关系、冲突优先级、清空规则明确。 | I35: 公共时间范围和报表自身时间范围互相打架。 | J35: 是什么 / 查询规则 | K35: 查询条件联动表 | L35: P1 | M35: L2-L4 | N35: 是 | R35: =IF(N35="否","不适用",IF(N35<>"是","待判断",IF(AND(O35="是",P35="是"),"通过",IF(O35="部分","待补充",IF(AND(O35="否",L35="P0"),"P0阻塞",IF(AND(O35="否",L35="P34"),"P34风险",IF(O35="否","建议优化","待检查"))))))) -> 待检查 | S35: 补查询联动和冲突处理规则。
A36: 35 | B36: 扩展检查 | C36: 列表查询与数据展示检查 | D36: 分页加载 | E36: 分页/加载更多/滚动加载 | F36: 列表数据可能较多 | G36: 是否分页？每页多少条？空态和加载失败怎么处理？ | H36: 分页方式、每页数量、总数展示、加载更多、空态、失败重试明确。 | I36: 数据量大但没有分页说明。 | J36: 是什么 / 展示规则 | K36: 分页规则表 | L36: P2 | M36: L1-L4 | N36: 是 | R36: =IF(N36="否","不适用",IF(N36<>"是","待判断",IF(AND(O36="是",P36="是"),"通过",IF(O36="部分","待补充",IF(AND(O36="否",L36="P0"),"P0阻塞",IF(AND(O36="否",L36="P35"),"P35风险",IF(O36="否","建议优化","待检查"))))))) -> 待检查 | S36: 补分页/加载规则。 | V36: 07_表格模板示例!A14｜规则表模板
A37: 36 | B37: 扩展检查 | C37: 列表查询与数据展示检查 | D37: 数据权限 | E37: 列表数据权限 | F37: 多组织、多部门、多角色、多租户或数据隔离场景 | G37: 不同角色能看到哪些数据？数据权限是否与按钮权限分离？ | H37: 数据范围、组织范围、部门范围、本人/本部门/全部规则明确。 | I37: 只控制按钮，不控制数据；低权限用户看到不该看的数据。 | J37: 是什么 / 数据权限 | K37: 数据权限矩阵 | L37: P0 | M37: L2-L4 | N37: 是 | R37: =IF(N37="否","不适用",IF(N37<>"是","待判断",IF(AND(O37="是",P37="是"),"通过",IF(O37="部分","待补充",IF(AND(O37="否",L37="P0"),"P0阻塞",IF(AND(O37="否",L37="P36"),"P36风险",IF(O37="否","建议优化","待检查"))))))) -> 待检查 | S37: 补数据权限矩阵。
A38: 37 | B38: 扩展检查 | C38: 操作交互与反馈检查 | D38: 点击状态 | E38: 点击前、中、后状态 | F38: 有保存、提交、审批、删除、批量处理等操作 | G38: 点击前、中、后页面状态分别是什么？是否防重复点击？ | H38: 点击前可用条件、点击中loading、防重复提交、点击后反馈与数据变化明确。 | I38: 只写“点击保存”，没写保存中和保存后。 | J38: 怎么玩 / 交互反馈 | K38: 交互状态表 | L38: P1 | M38: L1-L4 | N38: 是 | R38: =IF(N38="否","不适用",IF(N38<>"是","待判断",IF(AND(O38="是",P38="是"),"通过",IF(O38="部分","待补充",IF(AND(O38="否",L38="P0"),"P0阻塞",IF(AND(O38="否",L38="P37"),"P37风险",IF(O38="否","建议优化","待检查"))))))) -> 待检查 | S38: 补点击前中后状态。
A39: 38 | B39: 扩展检查 | C39: 操作交互与反馈检查 | D39: 二次确认 | E39: 高风险操作确认 | F39: 有删除、撤回、终止、启用、停用、覆盖、批量操作 | G39: 是否需要确认？确认文案、确认后结果、取消后结果是什么？ | H39: 触发动作、确认文案、主按钮/次按钮、确认结果、取消结果明确。 | I39: 只写“弹窗确认”，没有确认后状态和取消后结果。 | J39: 怎么玩 / 操作确认 | K39: 二次确认规则表 | L39: P1 | M39: L2-L4 | N39: 是 | R39: =IF(N39="否","不适用",IF(N39<>"是","待判断",IF(AND(O39="是",P39="是"),"通过",IF(O39="部分","待补充",IF(AND(O39="否",L39="P0"),"P0阻塞",IF(AND(O39="否",L39="P38"),"P38风险",IF(O39="否","建议优化","待检查"))))))) -> 待检查 | S39: 补二次确认规则。 | V39: 07_表格模板示例!A14｜规则表模板
A40: 39 | B40: 扩展检查 | C40: 操作交互与反馈检查 | D40: 弹窗规则 | E40: 弹窗行为与数据保留 | F40: 有新增、编辑、详情、选择、确认弹窗 | G40: 弹窗打开、关闭、取消、提交失败、数据保留规则是否明确？ | H40: 打开条件、关闭方式、取消行为、提交成功/失败、是否保留输入、是否刷新列表明确。 | I40: 只写“弹出编辑框”；关闭后数据是否保留不明。 | J40: 怎么玩 / 页面交互规则 | K40: 弹窗行为规则表 | L40: P1 | M40: L2-L4 | N40: 是 | R40: =IF(N40="否","不适用",IF(N40<>"是","待判断",IF(AND(O40="是",P40="是"),"通过",IF(O40="部分","待补充",IF(AND(O40="否",L40="P0"),"P0阻塞",IF(AND(O40="否",L40="P39"),"P39风险",IF(O40="否","建议优化","待检查"))))))) -> 待检查 | S40: 补弹窗行为规则；不写像素宽高，除非业务强依赖。 | V40: 07_表格模板示例!A14｜规则表模板
...

Sheet 02_字典配置
A1: 检查层级 | D1: 优先级 | G1: 是否适用 | J1: 是否已写 | M1: 是否已检查
A2: 必查门禁 | D2: P0 | G2: 是 | J2: 是 | M2: 是
A3: 扩展检查 | D3: P1 | G3: 否 | J3: 否 | M3: 否
A4: 优化建议 | D4: P2 | J4: 部分
D5: P3
A13: 实际问题等级 | D13: 门禁状态 | G13: 复杂度 | J13: 建议呈现方式 | M13: 修正动作类型
D14: 通过 | G14: L1 | J14: 范围表 | M14: 补规则
A15: P0 | D15: 待补充 | G15: L2 | J15: 非目标表 | M15: 补流程
A16: P1 | D16: P0阻塞 | G16: L3 | J16: 角色权限矩阵 | M16: 补状态机
A17: P2 | D17: P1风险 | G17: L4 | J17: 流程图 | M17: 补权限矩阵
A18: P3 | D18: 建议优化 | G18: L1-L4 | J18: 状态机图 | M18: 补数据口径
D19: 待检查 | G19: L2-L4 | J19: 规则表 | M19: 补异常兜底
D20: 不适用 | G20: L3-L4 | J20: 字段规则表 | M20: 补验收标准
D21: 待判断 | J21: 校验规则表 | M21: 进入待确认
J22: 数据口径表 | M22: 记录风险接受
J23: 异常规则表 | M23: 移至技术方案/设计说明
J24: 验收标准表
J25: 自测用例表
J26: 风险接受表

Sheet 03_阻塞标准
A1: 问题等级 | B1: 含义 | C1: 典型问题 | D1: 门禁行为 | E1: 处理规则
A2: P0 | B2: 致命问题 | C2: 真实问题不清、范围不清、核心流程不可执行、关键决策缺失、未确认事实写成事实、上下文冲突、明显越界 | D2: 必须阻塞最终输出和评审 | E2: 必须修正，不能仅标记风险接受；修正后重新审核相关章节
A3: P1 | B3: 高风险问题 | C3: 缺少非目标、异常处理、权限规则、状态变化、验收标准、上下游影响、数据来源或统计口径 | D3: 默认阻塞 | E3: 优先修正；如PM明确接受风险，必须记录原因、责任人和后续动作
A4: P2 | B4: 质量问题 | C4: 局部歧义、示例不足、验收偏粗、章节组织不顺、术语局部漂移 | D4: 不默认阻塞 | E4: 进入评审前建议修正；反复出现时进入模板或Skill迭代清单
A5: P3 | B5: 优化建议 | C5: 表达、格式、示例、顺序、可读性优化 | D5: 不阻塞 | E5: 不影响交付节奏时处理，不得因此扩大需求范围

Sheet 04_复杂度适配
A1: 复杂度 | B1: 需求类型 | C1: PRD最低要求 | D1: 重点检查 | E1: 典型适用场景
A2: L1 | B2: 文案、字段、配置、小规则调整 | C2: 可用变更说明，但必须写清变更点、影响范围、规则、验收方式 | D2: 范围、规则、验收、影响范围 | E2: 改字段名、增加小校验、调整提示文案
A3: L2 | B3: 单页面、单流程功能 | C3: 标准PRD，覆盖背景、范围、流程、规则、异常、验收 | D3: 主流程、字段规则、异常、验收 | E3: 新增一个配置页、一个列表页、一个审批动作
A4: L3 | B4: 多角色、多状态、多异常功能 | C4: 完整PRD，覆盖角色权限、状态流转、异常、上下游、数据边界 | D4: 权限、状态机、异常、数据、上下游、自测 | E4: 审批流、模板配置、消息中心、任务流转
A5: L4 | B5: 跨系统、跨模块、数据/权限/AI能力类需求 | C5: 完整PRD + 风险评审 + AI实现就绪检查 | D5: 能力边界、数据口径、系统依赖、低置信度/失败兜底、风险接受 | E5: 智能分析、跨系统同步、看板指标、复杂权限体系

Sheet 05_来源与原则
A1: 模块 | B1: 内容
A2: 根定义 | B2: 一份好的 PRD，不是把功能列全，而是把产品判断固定成团队可执行、可验证、可追责的共同答案。
A3: 唯一质量标准 | B3: 读的人不需要再回来找 PM 确认。
A4: 四个核心指标 | B4: 边界清晰、判断显性、不留猜疑、信息准确。
A5: PRD应写 | B5: 背景与问题、本期目标、范围与非目标、用户与角色、业务流程、功能规则、异常处理、权限规则、数据说明、验收标准、研发自测用例、待确认事项。
A6: PRD不应写 | B6: 数据库表结构、接口字段细节、代码逻辑、色号、像素、字号、未确认事实、未来想法混入本期。
A7: 使用原则 | B7: 复杂度可以影响文档篇幅，不能降低核心判断质量；小需求可以轻，但不能虚。
A8: 门禁原则 | B8: P0必须阻塞；P1默认阻塞，除非PM明确接受风险并记录原因；P2建议修正；P3仅作为优化建议。
A9: AI实现就绪 | B9: 无隐含默认值、无未标记假设、输入/处理/输出清楚、异常兜底清楚、验收用例明确。
A10: 来源说明 | B10: 根据用户上传的 PRD Quality Standard 与 PRD 定义与质量标准整理，并结合原始需求自查清单重构为 V3.2 质量门禁版。

Sheet 06_使用说明
A1: 步骤 | B1: 操作说明 | C1: 注意事项
A2: 1 | B2: 确认需求复杂度 | C2: 先判断需求属于 L1/L2/L3/L4，避免小需求被重型清单拖慢，也避免复杂需求写轻。
A3: 2 | B3: 筛选“是否适用” | C3: 在 01 表中将不适用项改为“否”；多角色、状态流转、数据统计类需求要重点保留 P0/P1 项。
A4: 3 | B4: 填写“是否已写” | C4: PRD 完整覆盖填“是”，完全没写填“否”，写了但不够可执行填“部分”。
A5: 4 | B5: 填写“是否已检查” | C5: 只有已核对 PRD 证据位置并确认达标，才填“是”。
A6: 5 | B6: 补充 PRD 证据位置 | C6: 填写章节号、表名、图名或段落位置，让评审人能快速定位证据。
A7: 6 | B7: 处理门禁状态 | C7: P0阻塞必须修正；P1风险默认修正，若接受风险，需要在风险接受表记录。
A8: 7 | B8: 查看评审看板 | C8: 回到 00_评审看板，确认 P0 清零、P1 已处理，再进入评审。
A9: 8 | B9: 复盘沉淀 | C9: 反复出现的 P2/P3 问题，应回写到 PRD 模板、Skill 规则或示例库中。
A11: V3.3 新增 | B11: 07_表格模板示例 | C11: 提供规则表、字段规则表、校验规则表、数据口径表、异常规则表、验收标准表、自测用例表、风险接受表的空白模板、示例数据和不合格写法。

Sheet 07_表格模板示例
A1: PRD 表格模板示例库｜V3.3
A2: 用途：当 01_需求自查清单 中出现“建议呈现方式”时，可在本页找到可复制的模板结构、示例数据与不合格写法。
A4: 模板名称 | B4: 适用场景 | C4: 解决的问题 | D4: 对应检查域 | E4: 常见 PRD 章节 | F4: 模板位置
A5: 规则表 | B5: 业务规则、操作规则、默认规则、状态规则 | C5: 把判断写死 | D5: 判断显性 | E5: 是什么 / 功能规则 | F5: A14｜规则表模板
A6: 字段规则表 | B6: 表单字段、列表字段、详情字段、配置字段 | C6: 把字段定义写清 | D6: 页面、表单与数据展示 | E6: 是什么 / 字段说明 | F6: A34｜字段规则表模板
A7: 校验规则表 | B7: 保存、提交、审批、发布前校验 | C7: 把拦截条件写清 | D7: 判断显性 / 不留猜疑 | E7: 怎么玩 / 校验规则 | F7: A54｜校验规则表模板
A8: 数据口径表 | B8: 看板、报表、统计指标、列表数据来源 | C8: 把数据来源和计算方式写清 | D8: 信息准确 | E8: 是什么 / 数据口径 | F8: A74｜数据口径表模板
A9: 异常规则表 | B9: 空态、失败、重复、冲突、权限不足 | C9: 把出岔子时怎么办写清 | D9: 异常、验收与测试 | E9: 怎么玩 / 异常兜底 | F9: A94｜异常规则表模板
A10: 验收标准表 | B10: 需求评审、测试验收、业务验收 | C10: 把完成标准写清 | D10: 不留猜疑 | E10: 验收标准 | F10: A116｜验收标准表模板
A11: 自测用例表 | B11: 研发交付前冒烟测试、PM 自查 | C11: 把最小可跑路径写清 | D11: 异常、验收与测试 | E11: 研发自测 | F11: A135｜自测用例表模板
A12: 风险接受表 | B12: P1 风险暂不修、待确认项暂挂起 | C12: 把风险接受留痕 | D12: 阻塞问题与评审结论 | E12: 风险接受 / 待确认事项 | F12: A154｜风险接受表模板
A14: B. 规则表模板
A15: 适用场景 | B15: 用于描述业务规则、操作规则、默认规则、状态规则。
A16: 使用说明 | B16: 必须回答：什么条件下，谁对什么对象做什么，系统如何处理，处理后结果是什么。
A17: 空白模板（可复制到 PRD）
A18: 规则编号 | B18: 规则对象 | C18: 适用场景 | D18: 触发条件 | E18: 规则说明 | F18: 系统处理 | G18: 处理后结果 | H18: 异常处理 | I18: 适用角色 | J18: 优先级 | K18: 备注
A20: 示例数据
A21: 规则编号 | B21: 规则对象 | C21: 适用场景 | D21: 触发条件 | E21: 规则说明 | F21: 系统处理 | G21: 处理后结果 | H21: 异常处理 | I21: 适用角色 | J21: 优先级 | K21: 备注
A22: R001 | B22: 审批提交 | C22: 作业票审批 | D22: 申请人点击提交审批 | E22: 仅当必填字段完整且当前状态为草稿时允许提交 | F22: 校验字段完整性并生成审批任务 | G22: 作业票状态变为待审批 | H22: 校验失败时阻断提交并提示原因 | I22: 申请人 | J22: P0 | K22: 需同步状态机
A23: R002 | B23: 删除操作 | C23: 模板管理 | D23: 管理员点击删除 | E23: 已被引用的数据不允许删除 | F23: 判断引用关系 | G23: 未引用则删除，已引用则阻断 | H23: 提示“该数据已被引用，无法删除” | I23: 管理员 | J23: P1 | K23: 建议逻辑删除
A24: 不合格写法
A25: 问题写法 | B25: 为什么不合格
A26: 支持审批 | B26: 没写触发条件、处理规则、处理结果
A27: 管理员可以删除 | B27: 没写哪些状态可删、被引用后能否删除
A28: 默认展示最新数据 | B28: 没写“最新”的排序字段和时间口径
A34: C. 字段规则表模板
A35: 适用场景 | B35: 用于描述表单字段、列表字段、详情字段、配置字段。
A36: 使用说明 | B36: 解决：字段是什么，谁填写，怎么填写，从哪里来，能不能改。
A37: 空白模板（可复制到 PRD）
A38: 字段名称 | B38: 字段含义 | C38: 字段类型 | D38: 输入/展示 | E38: 是否必填 | F38: 长度/格式 | G38: 默认值 | H38: 选项来源 | I38: 字段状态 | J38: 空值展示 | K38: 备注
A40: 示例数据
A41: 字段名称 | B41: 字段含义 | C41: 字段类型 | D41: 输入/展示 | E41: 是否必填 | F41: 长度/格式 | G41: 默认值 | H41: 选项来源 | I41: 字段状态 | J41: 空值展示 | K41: 备注
A42: 模板名称 | B42: 消息模板名称 | C42: 文本 | D42: 输入 | E42: 是 | F42: 1 到 32 字符 | G42: 无 | H42: 用户手动输入 | I42: 可编辑 | J42: 不适用 | K42: 同一业务模块下不可重复
A43: 启用状态 | B43: 模板是否启用 | C43: 开关 | D43: 输入 | E43: 是 | F43: 启用 / 停用 | G43: 启用 | H43: 系统固定枚举 | I43: 可编辑 | J43: 不适用 | K43: 停用后不触发消息
A44: 最近更新时间 | B44: 最近一次保存时间 | C44: 时间 | D44: 展示 | E44: 否 | F44: 年-月-日 时:分 | G44: 系统生成 | H44: 系统记录 | I44: 只读 | J44: -- | K44: 保存成功后自动更新
A45: 不合格写法
A46: 问题写法 | B46: 为什么不合格
A47: 填写名称 | B47: 没写长度、是否必填、是否重复、是否可编辑
A48: 展示更新时间 | B48: 没写时间格式、更新时间触发条件、空值展示
A54: D. 校验规则表模板
...
